# Rapport d'avancement à mi-parcours - Phase 2.3

## 1. Contexte

Ce rapport fait suite au précédent rapport et aux efforts de stabilisation de l'environnement de test qui ont été entrepris. L'objectif principal de cette phase était de résoudre les erreurs persistantes dans les tests, notamment les `sqlalchemy.exc.InterfaceError` et `RuntimeError`, afin de garantir la fiabilité de la base de code et de débloquer la suite du développement.

## 2. Progression et Réalisations

L'enquête sur les échecs des tests a révélé un problème fondamental dans la manière dont les tests interagissaient avec la base de données dans l'environnement conteneurisé.

### 2.1. Diagnostic : Erreur `sqlalchemy.exc.ArgumentError`

En isolant le problème avec un test de connexion à la base de données dédié (`test_db.py`), nous avons identifié que l'erreur n'était pas une `InterfaceError` (problème de connexion réseau) comme initialement suspecté, mais une `ArgumentError` levée par SQLAlchemy.

L'erreur `Textual SQL expression 'SELECT 1' should be explicitly declared as text('SELECT 1')` indiquait que les requêtes SQL brutes n'étaient pas correctement formatées pour la version de SQLAlchemy utilisée dans le projet.

### 2.2. Résolution

Le correctif a été simple et efficace :

1.  **Importation du module `text`** de SQLAlchemy.
2.  **Encapsulation de la requête SQL brute** dans la fonction `text()`.

Cette modification a permis au test de connexion à la base de données de s'exécuter avec succès, validant ainsi que la connexion à la base de données de test (`test-db`) est fonctionnelle depuis le conteneur `genesis-api`.

## 3. Prochaines Étapes

Maintenant que la connectivité de base à la base de données est confirmée et que la cause première de l'échec a été identifiée et corrigée, les prochaines étapes sont les suivantes :

1.  **Nettoyage** : Supprimer le fichier de test de diagnostic temporaire (`test_db.py`).
2.  **Ré-exécution des tests d'intégration** : Lancer à nouveau la suite de tests complète, en particulier `test_register_user`, pour confirmer que la résolution de `l'ArgumentError` a bien corrigé les échecs en cascade.
3.  **Poursuite de la feuille de route** : Une fois les tests stabilisés, nous reprendrons le développement des fonctionnalités prévues dans le plan de projet.

## 4. Conclusion

La résolution de ce problème de test, bien que technique, était une étape cruciale. Elle garantit que notre environnement de test est fiable, ce qui est essentiel pour maintenir la qualité et l'intégrité du code à mesure que nous ajoutons de nouvelles fonctionnalités. Nous sommes maintenant en bonne position pour accélérer le développement et atteindre les objectifs de la phase 2.